Workbook

Sheet EmployeeData
A1: EmployeeID | B1: Name | C1: Department | D1: JobRole | E1: City | F1: Experience | G1: Salary | H1: JoiningDate | I1: PerformanceRating
A2: E001 | B2: Rahul | C2: IT | D2: DataAnalyst | E2: Hyderabad | F2: 3 | G2: 55000 | H2: 44727 | I2: 4
A3: E002 | B3: Priya | C3: Finance | D3: FinancialAnalyst | E3: Mumbai | F3: 5 | G3: 72000 | H3: 43900 | I3: 5
A4: E003 | B4: Arjun | C4: HR | D4: HRExecutive | E4: Delhi | F4: 2 | G4: 48000 | H4: 45158 | I4: 3
A5: E004 | B5: Sneha | C5: IT | D5: DataEngineer | E5: Bangalore | F5: 6 | G5: 85000 | H5: 43470 | I5: 5
A6: E005 | B6: Kiran | C6: Sales | D6: SalesExecutive | E6: Pune | F6: 4 | G6: 62000 | H6: 44512 | I6: 4
A7: E006 | B7: Ananya | C7: Finance | D7: Accountant | E7: Mumbai | F7: 3 | G7: 58000 | H7: 44760 | I7: 4
A8: E007 | B8: Vikram | C8: IT | D8: SoftwareEngineer | E8: Hyderabad | F8: 7 | G8: 90000 | H8: 43156 | I8: 5
A9: E008 | B9: Meena | C9: HR | D9: HRManager | E9: Delhi | F9: 8 | G9: 78000 | H9: 42986 | I9: 4
A10: E009 | B10: Rohit | C10: Finance | D10: SeniorAccountant | E10: Pune | F10: 6 | G10: 75000 | H10: 43569 | I10: 5
A11: E010 | B11: Pooja | C11: IT | D11: BusinessAnalyst | E11: Bangalore | F11: 4 | G11: 68000 | H11: 44369 | I11: 4
A12: E011 | B12: Suresh | C12: Sales | D12: SalesManager | E12: Mumbai | F12: 9 | G12: 95000 | H12: 42380 | I12: 5
A13: E012 | B13: Divya | C13: HR | D13: Recruiter | E13: Hyderabad | F13: 3 | G13: 52000 | H13: 44864 | I13: 3
... A31: E030 | B31: Ramesh | C31: HR | D31: HRExecutive | E31: Bangalore | F31: 6 | G31: 67000 | H31: 43687 | I31: 4

Sheet Analysis
A1: Employee Analytics Project
A2: Employee Data Analysis | D2: Department Analysis
A3: Metric | B3: Value | D3: Department | E3: Employee Count | F3: Average Salary | G3: Highest Salary | H3: Lowest Salary | I3: Average Experience | J3: Average Performance Rating
A4: Total Employees | B4: =COUNTA(EmployeeData[EmployeeID]) -> 30 | D4: Finance | E4: =COUNTIF(EmployeeData[Department],D4) -> 8 | F4: =AVERAGEIF(EmployeeData[Department],D4,EmployeeData[Salary]) -> 68875 | G4: =_xlfn.MAXIFS(EmployeeData[Salary],EmployeeData[Department],D4) -> 88000 | H4: =_xlfn.MINIFS(EmployeeData[Salary],EmployeeData[Department],D4) -> 51000 | I4: =AVERAGEIFS(EmployeeData[Experience],EmployeeData[Department],D4) -> 4.75 | J4: =AVERAGEIFS(EmployeeData[PerformanceRating],EmployeeData[Department],D4) -> 4.375
A5: Average Salary | B5: =AVERAGE(EmployeeData[Salary]) -> 68333.333 | D5: HR | E5: =COUNTIF(EmployeeData[Department],D5) -> 7 | F5: =AVERAGEIF(EmployeeData[Department],D5,EmployeeData[Salary]) -> 63571.429 | G5: =_xlfn.MAXIFS(EmployeeData[Salary],EmployeeData[Department],D5) -> 95000 | H5: =_xlfn.MINIFS(EmployeeData[Salary],EmployeeData[Department],D5) -> 48000 | I5: =AVERAGEIFS(EmployeeData[Experience],EmployeeData[Department],D5) -> 5 | J5: =AVERAGEIFS(EmployeeData[PerformanceRating],EmployeeData[Department],D5) -> 3.7142857
A6: Highest Salary | B6: =MAX(EmployeeData[Salary]) -> 95000 | D6: IT | E6: =COUNTIF(EmployeeData[Department],D6) -> 9 | F6: =AVERAGEIF(EmployeeData[Department],D6,EmployeeData[Salary]) -> 71000 | G6: =_xlfn.MAXIFS(EmployeeData[Salary],EmployeeData[Department],D6) -> 90000 | H6: =_xlfn.MINIFS(EmployeeData[Salary],EmployeeData[Department],D6) -> 50000 | I6: =AVERAGEIFS(EmployeeData[Experience],EmployeeData[Department],D6) -> 4.5555556 | J6: =AVERAGEIFS(EmployeeData[PerformanceRating],EmployeeData[Department],D6) -> 4.2222222
A7: Lowest Salary | B7: =MIN(EmployeeData[Salary]) -> 47000 | D7: Sales | E7: =COUNTIF(EmployeeData[Department],D7) -> 6 | F7: =AVERAGEIF(EmployeeData[Department],D7,EmployeeData[Salary]) -> 69166.667 | G7: =_xlfn.MAXIFS(EmployeeData[Salary],EmployeeData[Department],D7) -> 95000 | H7: =_xlfn.MINIFS(EmployeeData[Salary],EmployeeData[Department],D7) -> 47000 | I7: =AVERAGEIFS(EmployeeData[Experience],EmployeeData[Department],D7) -> 5 | J7: =AVERAGEIFS(EmployeeData[PerformanceRating],EmployeeData[Department],D7) -> 4
A8: Average Experience | B8: =AVERAGE(EmployeeData[Experience]) -> 4.8
A9: Average Performance Rating | B9: =AVERAGE(EmployeeData[PerformanceRating]) -> 4.1
A11: Job Role Analysis
A13: Job Role | B13: Employee Count | C13: Average Salary
A14: DataAnalyst | B14: =COUNTIF(EmployeeData[JobRole],A14) -> 3 | C14: =AVERAGEIF(EmployeeData[JobRole],A14,EmployeeData[Salary]) -> 54000
A15: FinancialAnalyst | B15: =COUNTIF(EmployeeData[JobRole],A15) -> 3 | C15: =AVERAGEIF(EmployeeData[JobRole],A15,EmployeeData[Salary]) -> 74666.667
A16: HRExecutive | B16: =COUNTIF(EmployeeData[JobRole],A16) -> 3 | C16: =AVERAGEIF(EmployeeData[JobRole],A16,EmployeeData[Salary]) -> 57000
A17: DataEngineer | B17: =COUNTIF(EmployeeData[JobRole],A17) -> 2 | C17: =AVERAGEIF(EmployeeData[JobRole],A17,EmployeeData[Salary]) -> 82500
A18: SalesExecutive | B18: =COUNTIF(EmployeeData[JobRole],A18) -> 4 | C18: =AVERAGEIF(EmployeeData[JobRole],A18,EmployeeData[Salary]) -> 57000
A19: Accountant | B19: =COUNTIF(EmployeeData[JobRole],A19) -> 3 | C19: =AVERAGEIF(EmployeeData[JobRole],A19,EmployeeData[Salary]) -> 54666.667
A20: SoftwareEngineer | B20: =COUNTIF(EmployeeData[JobRole],A20) -> 2 | C20: =AVERAGEIF(EmployeeData[JobRole],A20,EmployeeData[Salary]) -> 84000
A21: HRManager | B21: =COUNTIF(EmployeeData[JobRole],A21) -> 2 | C21: =AVERAGEIF(EmployeeData[JobRole],A21,EmployeeData[Salary]) -> 86500
A22: SeniorAccountant | B22: =COUNTIF(EmployeeData[JobRole],A22) -> 2 | C22: =AVERAGEIF(EmployeeData[JobRole],A22,EmployeeData[Salary]) -> 81500
A23: BusinessAnalyst | B23: =COUNTIF(EmployeeData[JobRole],A23) -> 2 | C23: =AVERAGEIF(EmployeeData[JobRole],A23,EmployeeData[Salary]) -> 72000
A24: SalesManager | B24: =COUNTIF(EmployeeData[JobRole],A24) -> 2 | C24: =AVERAGEIF(EmployeeData[JobRole],A24,EmployeeData[Salary]) -> 93500
A25: Recruiter | B25: =COUNTIF(EmployeeData[JobRole],A25) -> 2 | C25: =AVERAGEIF(EmployeeData[JobRole],A25,EmployeeData[Salary]) -> 50500
A27: City Analysis
A29: City | B29: Employee Count | C29: Average Salary
A30: Hyderabad | B30: =COUNTIF(EmployeeData[City],A30) -> 6 | C30: =AVERAGEIF(EmployeeData[City],A30,EmployeeData[Salary]) -> 76666.667
A31: Mumbai | B31: =COUNTIF(EmployeeData[City],A31) -> 6 | C31: =AVERAGEIF(EmployeeData[City],A31,EmployeeData[Salary]) -> 75166.667
A32: Delhi | B32: =COUNTIF(EmployeeData[City],A32) -> 6 | C32: =AVERAGEIF(EmployeeData[City],A32,EmployeeData[Salary]) -> 64166.667
A33: Bangalore | B33: =COUNTIF(EmployeeData[City],A33) -> 6 | C33: =AVERAGEIF(EmployeeData[City],A33,EmployeeData[Salary]) -> 68833.333
A34: Pune | B34: =COUNTIF(EmployeeData[City],A34) -> 6 | C34: =AVERAGEIF(EmployeeData[City],A34,EmployeeData[Salary]) -> 56833.333
A36: Performance Rating Analysis
A38: Performance Rating | B38: Employee Count | C38: Average Salary
A39: 3 | B39: =COUNTIF(EmployeeData[PerformanceRating],A39) -> 7 | C39: =AVERAGEIF(EmployeeData[PerformanceRating],A39,EmployeeData[Salary]) -> 50142.857
A40: 4 | B40: =COUNTIF(EmployeeData[PerformanceRating],A40) -> 13 | C40: =AVERAGEIF(EmployeeData[PerformanceRating],A40,EmployeeData[Salary]) -> 65307.692
A41: 5 | B41: =COUNTIF(EmployeeData[PerformanceRating],A41) -> 10 | C41: =AVERAGEIF(EmployeeData[PerformanceRating],A41,EmployeeData[Salary]) -> 85000

Sheet Dashboard
A1: Employee Analytics Dashboard
A4: Total Employee | C4: Average Salary | E4: Highest Salary | G4: Lowest Salary | I4: Average Experience | K4: Avg Performance Rating
A5: =Analysis!B4 -> 30 | C5: =Analysis!B5 -> 68333.333 | E5: =Analysis!B6 -> 95000 | G5: =Analysis!B7 -> 47000 | I5: =Analysis!B8 -> 4.8 | K5: =Analysis!B9 -> 4.1
B8: Department Chart
A10: Department | B10: Employee Count | C10: Average Salary
A11: Finance | B11: =COUNTIF(EmployeeData[Department],A11) -> 8 | C11: =AVERAGEIF(EmployeeData[Department],A11,EmployeeData[Salary]) -> 68875
A12: HR | B12: =COUNTIF(EmployeeData[Department],A12) -> 7 | C12: =AVERAGEIF(EmployeeData[Department],A12,EmployeeData[Salary]) -> 63571.429
A13: IT | B13: =COUNTIF(EmployeeData[Department],A13) -> 9 | C13: =AVERAGEIF(EmployeeData[Department],A13,EmployeeData[Salary]) -> 71000
A14: Sales | B14: =COUNTIF(EmployeeData[Department],A14) -> 6 | C14: =AVERAGEIF(EmployeeData[Department],A14,EmployeeData[Salary]) -> 69166.667
B23: Job Role Chart
A25: Job Role | B25: Employee Count | C25: Average Salary
A26: DataAnalyst | B26: =COUNTIF(EmployeeData[JobRole],A26) -> 3 | C26: =AVERAGEIF(EmployeeData[JobRole],A26,EmployeeData[Salary]) -> 54000
A27: FinancialAnalyst | B27: =COUNTIF(EmployeeData[JobRole],A27) -> 3 | C27: =AVERAGEIF(EmployeeData[JobRole],A27,EmployeeData[Salary]) -> 74666.667
A28: HRExecutive | B28: =COUNTIF(EmployeeData[JobRole],A28) -> 3 | C28: =AVERAGEIF(EmployeeData[JobRole],A28,EmployeeData[Salary]) -> 57000
A29: DataEngineer | B29: =COUNTIF(EmployeeData[JobRole],A29) -> 2 | C29: =AVERAGEIF(EmployeeData[JobRole],A29,EmployeeData[Salary]) -> 82500
A30: SalesExecutive | B30: =COUNTIF(EmployeeData[JobRole],A30) -> 4 | C30: =AVERAGEIF(EmployeeData[JobRole],A30,EmployeeData[Salary]) -> 57000
A31: Accountant | B31: =COUNTIF(EmployeeData[JobRole],A31) -> 3 | C31: =AVERAGEIF(EmployeeData[JobRole],A31,EmployeeData[Salary]) -> 54666.667
A32: SoftwareEngineer | B32: =COUNTIF(EmployeeData[JobRole],A32) -> 2 | C32: =AVERAGEIF(EmployeeData[JobRole],A32,EmployeeData[Salary]) -> 84000
A33: HRManager | B33: =COUNTIF(EmployeeData[JobRole],A33) -> 2 | C33: =AVERAGEIF(EmployeeData[JobRole],A33,EmployeeData[Salary]) -> 86500
A34: SeniorAccountant | B34: =COUNTIF(EmployeeData[JobRole],A34) -> 2 | C34: =AVERAGEIF(EmployeeData[JobRole],A34,EmployeeData[Salary]) -> 81500
A35: BusinessAnalyst | B35: =COUNTIF(EmployeeData[JobRole],A35) -> 2 | C35: =AVERAGEIF(EmployeeData[JobRole],A35,EmployeeData[Salary]) -> 72000
A36: SalesManager | B36: =COUNTIF(EmployeeData[JobRole],A36) -> 2 | C36: =AVERAGEIF(EmployeeData[JobRole],A36,EmployeeData[Salary]) -> 93500
A37: Recruiter | B37: =COUNTIF(EmployeeData[JobRole],A37) -> 2 | C37: =AVERAGEIF(EmployeeData[JobRole],A37,EmployeeData[Salary]) -> 50500
B40: City Analysis Chart
A42: City | B42: Employee Count | C42: Average Salary
A43: Hyderabad | B43: =COUNTIF(EmployeeData[City],A43) -> 6 | C43: =AVERAGEIF(EmployeeData[City],A43,EmployeeData[Salary]) -> 76666.667
A44: Mumbai | B44: =COUNTIF(EmployeeData[City],A44) -> 6 | C44: =AVERAGEIF(EmployeeData[City],A44,EmployeeData[Salary]) -> 75166.667
A45: Delhi | B45: =COUNTIF(EmployeeData[City],A45) -> 6 | C45: =AVERAGEIF(EmployeeData[City],A45,EmployeeData[Salary]) -> 64166.667
A46: Bangalore | B46: =COUNTIF(EmployeeData[City],A46) -> 6 | C46: =AVERAGEIF(EmployeeData[City],A46,EmployeeData[Salary]) -> 68833.333
A47: Pune | B47: =COUNTIF(EmployeeData[City],A47) -> 6 | C47: =AVERAGEIF(EmployeeData[City],A47,EmployeeData[Salary]) -> 56833.333
B53: Performance Analysis Chart
A55: Performance Rating | B55: Employee Count | C55: Average Salary
A56: 3 | B56: =COUNTIF(EmployeeData[PerformanceRating],A56) -> 7 | C56: =AVERAGEIF(EmployeeData[PerformanceRating],A56,EmployeeData[Salary]) -> 50142.857
A57: 4 | B57: =COUNTIF(EmployeeData[PerformanceRating],A57) -> 13 | C57: =AVERAGEIF(EmployeeData[PerformanceRating],A57,EmployeeData[Salary]) -> 65307.692
A58: 5 | B58: =COUNTIF(EmployeeData[PerformanceRating],A58) -> 10 | C58: =AVERAGEIF(EmployeeData[PerformanceRating],A58,EmployeeData[Salary]) -> 85000
B66: Average Salary Chart
A68: Department | B68: Average Salary
A69: Finance | B69: =AVERAGEIF(EmployeeData[Department],A69,EmployeeData[Salary]) -> 68875
A70: HR | B70: =AVERAGEIF(EmployeeData[Department],A70,EmployeeData[Salary]) -> 63571.429
A71: IT | B71: =AVERAGEIF(EmployeeData[Department],A71,EmployeeData[Salary]) -> 71000
...
